
STARTING DAFFE TESTS AT: Mon Mar 23 18:36:07 CET 2015

NOTES:
- nsec values is database downtime
- min/sec value is migration duration
- Application starts and ends at DAFFE1


----------------------------------------
 DATA INCREMENT OF: 2 records (4K)

Mon Mar 23 18:36:17.051 Error: couldn't connect to server 145.100.108.226:27017 at src/mongo/shell/mongo.js:147
exception: connect failed

real	0m0.035s
user	0m0.030s
sys	0m0.004s
----------------------------------------

----------------------------------------
 DEPLOYMENT: daffeflock-deployment3.yml
----------------------------------------
MONGODB MIGRATION TIMINGS:
main function encountered error
Traceback (most recent call last):
Failure: twisted.internet.defer.FirstError: FirstError[#1, [Failure instance: Traceback (failure with no frames): <class 'flocker.volume.filesystems.zfs.CommandFailed'>: 
]]
main function encountered error
Traceback (most recent call last):
  File "/usr/lib/python2.7/threading.py", line 783, in __bootstrap
    self.__bootstrap_inner()
  File "/usr/lib/python2.7/threading.py", line 810, in __bootstrap_inner
    self.run()
  File "/usr/lib/python2.7/threading.py", line 763, in run
    self.__target(*self.__args, **self.__kwargs)
--- <exception caught here> ---
  File "/home/thijs/Documents/Studie/LIA/flocker-tutorial/local/lib/python2.7/site-packages/twisted/python/threadpool.py", line 196, in _worker
    result = context.call(ctx, function, *args, **kwargs)
  File "/home/thijs/Documents/Studie/LIA/flocker-tutorial/local/lib/python2.7/site-packages/twisted/python/context.py", line 118, in callWithContext
    return self.currentContext().callWithContext(ctx, func, *args, **kw)
  File "/home/thijs/Documents/Studie/LIA/flocker-tutorial/local/lib/python2.7/site-packages/twisted/python/context.py", line 81, in callWithContext
    return func(*args,**kw)
  File "/home/thijs/Documents/Studie/LIA/flocker-tutorial/local/lib/python2.7/site-packages/flocker/common/_ipc.py", line 90, in get_output
    raise IOError("Bad exit", remote_command, e.returncode, e.output)
exceptions.IOError: ('Bad exit', ['flocker-reportstate'], 1, '')

real	0m8.912s
user	0m0.286s
sys	0m0.137s
