
STARTING DAFFE TESTS AT: Sun Mar 29 17:53:13 CEST 2015


RECORDS: 300000

NOTES:
- nsec values is database downtime
- min/sec value is migration duration
- Application starts and ends at DAFFE2


----------------------------------------
 DATA INCREMENT OF: 300000 records (4K)

938.87 seconds init
----------------------------------------


----------------------------------------
 DEPLOYMENT: daffeflock-deployment4.yml
 IP ADDRESS: 54.145.165.251
----------------------------------------
MONGODB MIGRATION TIMINGS:
488.09 seconds migration
31279523771 nsec DB downtime

MONGODB BYTES DIRECT: 1224150928
MONGODB COUNT DIRECT: 303138
MONGODB COUNT HTTP:   303138
MONGODB TIMES HTTP:   303138 count reported with connection timings:
    time_namelookup:  0.000
       time_connect:  0.115
    time_appconnect:  0.000
   time_pretransfer:  0.115
      time_redirect:  0.000
 time_starttransfer:  0.236
                    ----------
         time_total:  0.236
-----


----------------------------------------
 DEPLOYMENT: daffeflock-deployment5.yml
 IP ADDRESS: 54.177.53.81
----------------------------------------
MONGODB MIGRATION TIMINGS:
395.26 seconds migration
30083131347 nsec DB downtime

MONGODB BYTES DIRECT: 1224208336
MONGODB COUNT DIRECT: 304334
MONGODB COUNT HTTP:   304334
MONGODB TIMES HTTP:   304334 count reported with connection timings:
    time_namelookup:  0.000
       time_connect:  0.211
    time_appconnect:  0.000
   time_pretransfer:  0.211
      time_redirect:  0.000
 time_starttransfer:  0.389
                    ----------
         time_total:  0.389
-----


----------------------------------------
 DEPLOYMENT: daffeflock-deployment6.yml
 IP ADDRESS: 175.41.186.101
----------------------------------------
MONGODB MIGRATION TIMINGS:
523.28 seconds migration
33548176853 nsec DB downtime

MONGODB BYTES DIRECT: 1224264640
MONGODB COUNT DIRECT: 305507
MONGODB COUNT HTTP:   305507
MONGODB TIMES HTTP:   305507 count reported with connection timings:
    time_namelookup:  0.000
       time_connect:  0.362
    time_appconnect:  0.000
   time_pretransfer:  0.362
      time_redirect:  0.000
 time_starttransfer:  0.769
                    ----------
         time_total:  0.769
-----


----------------------------------------
 DEPLOYMENT: daffeflock-deployment3.yml
 IP ADDRESS: 54.247.130.237
----------------------------------------
MONGODB MIGRATION TIMINGS:
Unhandled Error
Traceback (most recent call last):
  File "/usr/lib/python2.7/site-packages/flocker/volume/filesystems/zfs.py", line 596, in enumerate
    listing = _list_filesystems(self._reactor, self._name)
  File "/usr/lib/python2.7/site-packages/flocker/volume/filesystems/zfs.py", line 644, in _list_filesystems
    pool])
  File "/usr/lib/python2.7/site-packages/flocker/volume/filesystems/zfs.py", line 93, in zfs_command
    d = connectProtocol(endpoint, _AccumulatingProtocol())
  File "/usr/lib64/python2.7/site-packages/twisted/internet/endpoints.py", line 1783, in connectProtocol
    return endpoint.connect(OneShotFactory())
--- <exception caught here> ---
  File "/usr/lib64/python2.7/site-packages/twisted/internet/endpoints.py", line 424, in connect
    self._gid, self._usePTY, self._childFDs)
  File "/usr/lib64/python2.7/site-packages/twisted/internet/posixbase.py", line 345, in spawnProcess
    processProtocol, uid, gid, childFDs)
  File "/usr/lib64/python2.7/site-packages/twisted/internet/process.py", line 677, in __init__
    self._fork(path, uid, gid, executable, args, environment, fdmap=fdmap)
  File "/usr/lib64/python2.7/site-packages/twisted/internet/process.py", line 382, in _fork
    self.pid = os.fork()
exceptions.OSError: [Errno 12] Cannot allocate memory
main function encountered error
Traceback (most recent call last):
Failure: twisted.internet.defer.FirstError: FirstError[#0, [Failure instance: Traceback: <type 'exceptions.OSError'>: [Errno 12] Cannot allocate memory
/usr/lib/python2.7/site-packages/flocker/volume/filesystems/zfs.py:596:enumerate
/usr/lib/python2.7/site-packages/flocker/volume/filesystems/zfs.py:644:_list_filesystems
/usr/lib/python2.7/site-packages/flocker/volume/filesystems/zfs.py:93:zfs_command
/usr/lib64/python2.7/site-packages/twisted/internet/endpoints.py:1783:connectProtocol
--- <exception caught here> ---
/usr/lib64/python2.7/site-packages/twisted/internet/endpoints.py:424:connect
/usr/lib64/python2.7/site-packages/twisted/internet/posixbase.py:345:spawnProcess
/usr/lib64/python2.7/site-packages/twisted/internet/process.py:677:__init__
/usr/lib64/python2.7/site-packages/twisted/internet/process.py:382:_fork
]]
warning: cannot send 'flocker/3f0e72e4-830e-41f5-adeb-51b5b378d2a9.default.mongodb@5fdc7c86-7d06-45c1-b543-27cb674074e5': Broken pipe
Unhandled Error
Traceback (most recent call last):
  File "/usr/lib/python2.7/site-packages/flocker/node/_deploy.py", line 255, in run
    RemoteVolumeManager(destination))
  File "/usr/lib/python2.7/site-packages/flocker/volume/service.py", line 297, in push
    pushing = getting_snapshots.addCallback(got_snapshots)
  File "/usr/lib64/python2.7/site-packages/twisted/internet/defer.py", line 306, in addCallback
    callbackKeywords=kw)
  File "/usr/lib64/python2.7/site-packages/twisted/internet/defer.py", line 295, in addCallbacks
    self._runCallbacks()
--- <exception caught here> ---
  File "/usr/lib64/python2.7/site-packages/twisted/internet/defer.py", line 577, in _runCallbacks
    current.result = callback(current.result, *args, **kw)
  File "/usr/lib/python2.7/site-packages/flocker/volume/service.py", line 295, in got_snapshots
    receiver.write(chunk)
  File "/usr/lib64/python2.7/contextlib.py", line 35, in __exit__
    self.gen.throw(type, value, traceback)
  File "/usr/lib/python2.7/site-packages/flocker/common/_ipc.py", line 80, in run
    raise IOError("Bad exit", remote_command, exit_code)
exceptions.IOError: [Errno Bad exit] ['flocker-volume', '--config', '/etc/flocker/volume.json', 'receive', '3f0e72e4-830e-41f5-adeb-51b5b378d2a9', 'default.mongodb']: 255
main function encountered error
Traceback (most recent call last):
Failure: twisted.internet.defer.FirstError: FirstError[#0, [Failure instance: Traceback: <type 'exceptions.IOError'>: [Errno Bad exit] ['flocker-volume', '--config', '/etc/flocker/volume.json', 'receive', '3f0e72e4-830e-41f5-adeb-51b5b378d2a9', 'default.mongodb']: 255
/usr/lib/python2.7/site-packages/flocker/node/_deploy.py:255:run
/usr/lib/python2.7/site-packages/flocker/volume/service.py:297:push
/usr/lib64/python2.7/site-packages/twisted/internet/defer.py:306:addCallback
/usr/lib64/python2.7/site-packages/twisted/internet/defer.py:295:addCallbacks
--- <exception caught here> ---
/usr/lib64/python2.7/site-packages/twisted/internet/defer.py:577:_runCallbacks
/usr/lib/python2.7/site-packages/flocker/volume/service.py:295:got_snapshots
/usr/lib64/python2.7/contextlib.py:35:__exit__
/usr/lib/python2.7/site-packages/flocker/common/_ipc.py:80:run
]]
Unhandled error in Deferred:
Unhandled Error
Traceback (most recent call last):
  File "/usr/lib/python2.7/threading.py", line 783, in __bootstrap
    self.__bootstrap_inner()
  File "/usr/lib/python2.7/threading.py", line 810, in __bootstrap_inner
    self.run()
  File "/usr/lib/python2.7/threading.py", line 763, in run
    self.__target(*self.__args, **self.__kwargs)
--- <exception caught here> ---
  File "/home/thijs/Documents/Studie/LIA/flocker-tutorial/local/lib/python2.7/site-packages/twisted/python/threadpool.py", line 196, in _worker
    result = context.call(ctx, function, *args, **kwargs)
  File "/home/thijs/Documents/Studie/LIA/flocker-tutorial/local/lib/python2.7/site-packages/twisted/python/context.py", line 118, in callWithContext
    return self.currentContext().callWithContext(ctx, func, *args, **kw)
  File "/home/thijs/Documents/Studie/LIA/flocker-tutorial/local/lib/python2.7/site-packages/twisted/python/context.py", line 81, in callWithContext
    return func(*args,**kw)
  File "/home/thijs/Documents/Studie/LIA/flocker-tutorial/local/lib/python2.7/site-packages/flocker/common/_ipc.py", line 90, in get_output
    raise IOError("Bad exit", remote_command, e.returncode, e.output)
exceptions.IOError: ('Bad exit', ['flocker-changestate', '"version": 1\n"nodes":\n#  "145.100.108.226": []\n#  "145.100.108.227": []\n  "54.247.130.237": ["mongodb", "daffedummy"]\n  "54.145.165.251": []\n  "54.177.53.81": []\n  "175.41.186.101": []\n\n', '"version": 1\n"applications":\n  "mongodb":\n    "image": "daffe/mongodb"\n    "ports":\n     - "internal": 27017\n       "external": 27017\n    "volume":\n      "mountpoint": "/data/db"\n  "daffedummy":\n    "image": "daffe/daffedummy"\n    "environment":\n       "TEST_VARIABLE": "DAFFE1337"\n    "links":\n     - "local_port": 27017\n       "remote_port": 27017\n       "alias": "mongo"\n    "ports":\n     - "internal": 8080\n       "external": 8080\n', '175.41.186.101:\n  applications:\n    daffedummy:\n      image: daffe/daffedummy:latest\n      ports:\n      - {external: 8080, internal: 8080}\n    mongodb:\n      image: daffe/mongodb:latest\n      ports:\n      - {external: 27017, internal: 27017}\n      volume: {mountpoint: /data/db}\n  used_ports: [22, 8080, 27017]\n  version: 1\n54.145.165.251:\n  applications: {}\n  used_ports: [22, 8080, 27017]\n  version: 1\n54.177.53.81:\n  applications: {}\n  used_ports: [22, 8080, 27017]\n  version: 1\n54.247.130.237:\n  applications: {}\n  used_ports: [22, 8080, 27017]\n  version: 1\n', '54.247.130.237'], 1, '')
Unhandled error in Deferred:
Unhandled Error
Traceback (most recent call last):
  File "/usr/lib/python2.7/threading.py", line 783, in __bootstrap
    self.__bootstrap_inner()
  File "/usr/lib/python2.7/threading.py", line 810, in __bootstrap_inner
    self.run()
  File "/usr/lib/python2.7/threading.py", line 763, in run
    self.__target(*self.__args, **self.__kwargs)
--- <exception caught here> ---
  File "/home/thijs/Documents/Studie/LIA/flocker-tutorial/local/lib/python2.7/site-packages/twisted/python/threadpool.py", line 196, in _worker
    result = context.call(ctx, function, *args, **kwargs)
  File "/home/thijs/Documents/Studie/LIA/flocker-tutorial/local/lib/python2.7/site-packages/twisted/python/context.py", line 118, in callWithContext
    return self.currentContext().callWithContext(ctx, func, *args, **kw)
  File "/home/thijs/Documents/Studie/LIA/flocker-tutorial/local/lib/python2.7/site-packages/twisted/python/context.py", line 81, in callWithContext
    return func(*args,**kw)
  File "/home/thijs/Documents/Studie/LIA/flocker-tutorial/local/lib/python2.7/site-packages/flocker/common/_ipc.py", line 90, in get_output
    raise IOError("Bad exit", remote_command, e.returncode, e.output)
exceptions.IOError: ('Bad exit', ['flocker-changestate', '"version": 1\n"nodes":\n#  "145.100.108.226": []\n#  "145.100.108.227": []\n  "54.247.130.237": ["mongodb", "daffedummy"]\n  "54.145.165.251": []\n  "54.177.53.81": []\n  "175.41.186.101": []\n\n', '"version": 1\n"applications":\n  "mongodb":\n    "image": "daffe/mongodb"\n    "ports":\n     - "internal": 27017\n       "external": 27017\n    "volume":\n      "mountpoint": "/data/db"\n  "daffedummy":\n    "image": "daffe/daffedummy"\n    "environment":\n       "TEST_VARIABLE": "DAFFE1337"\n    "links":\n     - "local_port": 27017\n       "remote_port": 27017\n       "alias": "mongo"\n    "ports":\n     - "internal": 8080\n       "external": 8080\n', '175.41.186.101:\n  applications:\n    daffedummy:\n      image: daffe/daffedummy:latest\n      ports:\n      - {external: 8080, internal: 8080}\n    mongodb:\n      image: daffe/mongodb:latest\n      ports:\n      - {external: 27017, internal: 27017}\n      volume: {mountpoint: /data/db}\n  used_ports: [22, 8080, 27017]\n  version: 1\n54.145.165.251:\n  applications: {}\n  used_ports: [22, 8080, 27017]\n  version: 1\n54.177.53.81:\n  applications: {}\n  used_ports: [22, 8080, 27017]\n  version: 1\n54.247.130.237:\n  applications: {}\n  used_ports: [22, 8080, 27017]\n  version: 1\n', '175.41.186.101'], 1, '')
14298.61 seconds migration

MONGODB BYTES DIRECT: Sun Mar 29 22:34:25.881 Error: couldn't connect to server 54.247.130.237:27017 at src/mongo/shell/mongo.js:147
MONGODB COUNT DIRECT: Sun Mar 29 22:34:31.975 Error: couldn't connect to server 54.247.130.237:27017 at src/mongo/shell/mongo.js:147
MONGODB COUNT HTTP:   
MONGODB TIMES HTTP:    count reported with connection timings:
    time_namelookup:  0.000
       time_connect:  0.000
    time_appconnect:  0.000
   time_pretransfer:  0.000
      time_redirect:  0.000
 time_starttransfer:  0.000
                    ----------
         time_total:  126.318
-----

DAFFE TESTS DONE AT: Sun Mar 29 23:21:28 CEST 2015

